Workbook

Sheet Notes
B2: Water Temp settings is affected by the removal of the thermistor
B3: for example: for the quick program, the default setting is cold becasuse if it is warm we will take such long time to get hot water after cold water in case user forgot to attach the hot water

Sheet Layout
B2: Sharp VE BLDC 11/13kg
F20: Programs: | H20: Options: | J20: Maunal Selection: | N20: Option Selection:
F21: Regular | H21: Anti-Wrinkle | J21: 1. 3-WATER-TEMP : COLD/WARM/HOT. 2. 4-WASH-TIME : 3-MIN, 9-MIN, 12-MIN, 18-MIN. 3. 3-RINSE TIMES : 1-TIME, 2-TIME, 3-TIME. 4. 4-SPIN-TIME : 1-MIN, 5-MIN, 9-MIN, SUPER SPIN 5. 4-WATER-LEVEL : 1-LEVEL, 2-LEVEL, 3-LEVEL, 4-LEVEL | N21: 1. Soak: 1,2,4 h 2. Anti-Wrinkle: 2 min 3. Delay Start: 1-12 h
F22: Quick | H22: Delay Start
F23: Heavy | H23: Soak
F24: Baby Care | H24: Child Lock
F25: Cotton
F26: Delicates
F27: Wool
F28: Quick Rinse
F29: Jeans
F30: Blanket
F31: Tub Clean
F32: Sports Wear

Sheet Differences Summary
B2: First: BLDC VS AC
B3: The differences between washing machine models with AC & BLDC motor are summarized below:
B4: (11/13kg models)
C6: Item | E6: Sharp AC | F6: Sharp BLDC | G6: Notes
C7: No. of Programs | E7: 10 | F7: 12 | G7: The 2 extra programs in BLDC model are: Quick Rinse & Sports Wear
C8: 7-segment | E8: 4 digits | F8: 3 digits
C9: Balance Spin Curve | E9: ON/OFF | F9: Spin Curve
B11: Second: Tornado VS Sharp BLDC
B12: The differences between Tornado & Sharp washing machines are summarized below:
C14: Item | E14: Tornado VE 11/13kg | G14: Sharp VE 11/13kg | I14: Notes
C15: No. of Programs | E15: 9 | G15: 12 | I15: In Tornado Tub Clean became on the option list not a program
C16: Program List Excluding Tub Clean | E16: Regular | G16: Regular | I16: Program List is identical for both Sharp & Tornado with 2 extra programs in Sharp
E17: Rapid | G17: Quick
E18: Heavy | G18: Heavy
E19: Baby Care | G19: Baby Care
E20: Cotton | G20: Cotton
E21: Delicate | G21: Delicates
E22: Wool | G22: Wool
E23: Jeans | G23: Jeans
E24: Blanket | G24: Blanket
G25: Quick Rinse
G26: Sports Wear
C27: Tub Clean (Yes/ No) | E27: Yes | G27: Yes
C28: Option List Excluding Tub Clean | E28: Extra Spin | G28: (Super Spin found in the spin options list) | I28: Easy Iron is the same as Anti-Wrinkle Feature
E29: Stain LVL | G29: No Stain LVL
E30: Soak | G30: Soak
E31: Child Lock | G31: Child Lock
E32: Easy Iron | G32: Anti-Wrinkle
E33: Delay Start | G33: Delay Start
B35: Third: 11kg VS 13kg Model
B36: Sharp VE BLDC 11/13kg Software Versions:
B38: The difference is descriped in the table below:
B39: For 4th water level only.
C41: WM | D41: Water amount before M2
C42: Sharp VE BLDC 11kg | D42: 90
C43: Sharp VE BLDC 13kg | D43: 93

Sheet Blockdiagram

Sheet Course Option
C2: Index: = Program Default, = Available Select, X = Not Available, = Selection Order
B4: Buttons/ Process | C4: Select Contents | D4: Program Default Avaliable Selection for Each Program Courses
D5: Regular | E5: Quick | F5: Heavy | G5: Baby Care | H5: Cotton | I5: Delicates | J5: Wool | K5: Quick Rinse | L5: Jeans | M5: Blanket | N5: Tub Clean | O5: Sports Wear
B6: Weight Detection - cancelled when WL is manually selected | I6: X | J6: X | M6: X | N6: X
B7: Water Temp. | C7: Cold
C8: Warm | E8: X | J8: X
C9: Hot | E9: X | I9: X | J9: X | O9: X
B10: Wash Time* | C10: 3 min | N10: X
C11: 9 min | N11: X
C12: 12 min | J12: X | N12: X
C13: 18 min | J13: X | N13: X
B14: Rinse Times | C14: 1 time | N14: X
C15: 2 times | N15: X
C16: 3 times | J16: X | N16: X
B17: Spin Time | C17: 1 min | N17: X
C18: 5 min | N18: X
C19: 9 min | E19: X | I19: X | J19: X | N19: X | O19: X
C20: 20 min (SS) | E20: X | I20: X | J20: X | N20: X | O20: X
B21: Water Level | C21: LEV-1 | I21: X | J21: X | N21: X
C22: LEV-2 | I22: X | J22: X | N22: X
C23: LEV-3 | N23: X
C24: LEV-4 | N24: X
B25: Soak | C25: 1 hour | E25: X | J25: X | N25: X
C26: 2 hours | E26: X | J26: X | N26: X
C27: 4 hours | E27: X | J27: X | N27: X
B28: Anti-Wrinkle | C28: 2 min | E28: X | I28: X | J28: X | M28: X | N28: X | O28: X
B29: Delay Start (1 hour - 12 hour)
B31: *For programs with weight detection:
B32: when weight detection leads to selecting water level 1 default wash time will change (refer to sequence charts tab)

Sheet Sequence Chart
F1: Index:
F2: Options | H2: Level 1 | J2: Level 2 | L2: Level 3 | N2: Level 4 | P2: Not Applicable | S2: Based on Selection | U2: Time will be modified accordingly | Y2: Bold water level is the default selection
B3: Process | D3: Selectable | F3: Regular | J3: Quick | N3: Heavy | R3: Baby Care | V3: Cotton | Z3: Delicates | AD3: Wool | AH3: Jeans | AL3: Quick Rinse | AP3: Sports Wear
C4: Detail Process | E4: Time | F4: LEV-1 | G4: LEV-2 | H4: LEV-3 | I4: LEV-4 | J4: LEV-1 | K4: LEV-2 | L4: LEV-3 | M4: LEV-4 | N4: LEV-1 | O4: LEV-2 | P4: LEV-3 | Q4: LEV-4 | R4: LEV-1 | S4: LEV-2 | T4: LEV-3 | U4: LEV-4 | V4: LEV-1 | W4: LEV-2 | X4: LEV-3 | Y4: LEV-4 | Z4: LEV-1 | AA4: LEV-2 | AB4: LEV-3 | AC4: LEV-4 | AD4: LEV-1 | AE4: LEV-2 | AF4: LEV-3 | AG4: LEV-4 | AH4: LEV-1 | AI4: LEV-2 | AJ4: LEV-3 | AK4: LEV-4 | AL4: LEV-1 | AM4: LEV-2 | AN4: LEV-3 | AO4: LEV-4 | AP4: LEV-1 | AQ4: LEV-2 | AR4: LEV-3 | AS4: LEV-4
B5: Delay Start | D5: 1-12hr | F5: 1-12hr | J5: 1-12hr | N5: 1-12hr | R5: 1-12hr | V5: 1-12hr | AB5: 1-12hr | AF5: 1-12hr | AH5: 1-12hr | AL5: 1-12hr | AP5: 1-12hr
B6: Wash & Soak | C6: Weight Detection | D6: ok | E6: 7.2 sec | F6: ok | G6: ok | H6: ok | I6: ok | J6: ok | K6: ok | L6: ok | M6: ok | N6: ok | O6: ok | P6: ok | Q6: ok | R6: ok | S6: ok | T6: ok | U6: ok | V6: ok | W6: ok | X6: ok | Y6: ok | AB6: ok | AC6: ok | AF6: ok | AG6: ok | AH6: ok | AI6: ok | AJ6: ok | AK6: ok | AL6: ok | AM6: ok | AN6: ok | AO6: ok | AP6: ok | AQ6: ok | AR6: ok | AS6: ok
C7: Water Filling (Time : min) | D7: LEV-1 | E7: 3 min | F7: 0.0020833333 | G7: 0.0027777778 | H7: 0.0034722222 | I7: 0.0041666667 | J7: 0.0020833333 | K7: 0.0027777778 | L7: 0.0034722222 | M7: 0.0041666667 | N7: 0.0020833333 | O7: 0.0027777778 | P7: 0.0034722222 | Q7: 0.0041666667 | R7: 0.0020833333 | S7: 0.0027777778 | T7: 0.0034722222 | U7: 0.0041666667 | V7: 0.0020833333 | W7: 0.0027777778 | X7: 0.0034722222 | Y7: 0.0041666667 | AB7: 0.0034722222 | AC7: 0.0041666667 | AF7: 0.0034722222 | AG7: 0.0041666667 | AH7: 0.0020833333 | AI7: 0.0027777778 | AJ7: 0.0034722222 | AK7: 0.0041666667 | AL7: 0 | AM7: 0 | AN7: 0 | AO7: 0 | AP7: 0.0020833333 | AQ7: 0.0027777778 | AR7: 0.0034722222 | AS7: 0.0041666667
D8: LEV-2 | E8: 4 min
D9: LEV-3 | E9: 5 min
D10: LEV-4 | E10: 6 min
C11: Soak | D11: _ | E11: 1 hour | F11: 0 | J11: XXX | N11: 0 | R11: 0 | V11: 0 | Z11: XXX | AD11: XXX | AH11: 0 | AL11: 0 | AP11: 0
D12: _ | E12: 2 hour | J12: XXX | Z12: XXX | AD12: XXX
D13: _ | E13: 4 hour | J13: XXX | Z13: XXX | AD13: XXX
C14: Main Wash (Time : min) | D14: _ | E14: 3 min | F14: 0.0020833333 | G14: 0.0083333333 | H14: 0.0083333333 | I14: 0.0083333333 | J14: 0.0020833333 | K14: 0.0020833333 | L14: 0.0020833333 | M14: 0.0020833333 | N14: 0.0020833333 | O14: 0.0125 | P14: 0.0125 | Q14: 0.0125 | R14: 0.0020833333 | S14: 0.0083333333 | T14: 0.0083333333 | U14: 0.0083333333 | V14: 0.0020833333 | W14: 0.0125 | X14: 0.0125 | Y14: 0.0125 | AB14: 0.00625 | AC14: 0.00625 | AF14: 0.00625 | AG14: 0.00625 | AH14: 0.0020833333 | AI14: 0.0125 | AJ14: 0.0125 | AK14: 0.0125 | AL14: 0 | AM14: 0 | AN14: 0 | AO14: 0 | AP14: 0.0020833333 | AQ14: 0.00625 | AR14: 0.00625 | AS14: 0.00625
D15: _ | E15: 9 min
D16: _ | E16: 12 min
D17: _ | E17: 18 min
C18: Wash Time (min) | F18: =F7+F14 -> 0.0041666667 | G18: =G7+G14 -> 0.011111111 | H18: =H14+H7 -> 0.011805556 | I18: =I7+I14 -> 0.0125 | J18: =J7+J14 -> 0.0041666667 | K18: =K7+K14 -> 0.0048611111 | L18: =L14+L7 -> 0.0055555556 | M18: =M7+M14 -> 0.00625 | N18: =N7+N14 -> 0.0041666667 | O18: =O7+O14 -> 0.015277778 | P18: =P14+P7 -> 0.015972222 | Q18: =Q7+Q14 -> 0.016666667 | R18: =R7+R14 -> 0.0041666667 | S18: =S7+S14 -> 0.011111111 | T18: =T14+T7 -> 0.011805556 | U18: =U7+U14 -> 0.0125 | V18: =V7+V14 -> 0.0041666667 | W18: =W7+W14 -> 0.015277778 | X18: =X14+X7 -> 0.015972222 | Y18: =Y7+Y14 -> 0.016666667 | AB18: =AB14+AB7 -> 0.0097222222 | AC18: =AC7+AC14 -> 0.010416667 | AF18: =AF14+AF7 -> 0.0097222222 | AG18: =AG7+AG14 -> 0.010416667 | AH18: =AH7+AH14 -> 0.0041666667 | AI18: =AI7+AI14 -> 0.015277778 | AJ18: =AJ14+AJ7 -> 0.015972222 | AK18: =AK7+AK14 -> 0.016666667 | AL18: =AL7+AL14 -> 0 | AM18: =AM7+AM14 -> 0 | AN18: =AN14+AN7 -> 0 | AO18: =AO7+AO14 -> 0 | AP18: =AP7+AP14 -> 0.0041666667 | AQ18: =AQ7+AQ14 -> 0.0090277778 | AR18: =AR14+AR7 -> 0.0097222222 | AS18: =AS7+AS14 -> 0.010416667
B19: Rinse 1,2,3 | C19: Rinse Count (Repeated Rinse Times) | F19: 2 | G19: 2 | H19: 2 | I19: 2 | J19: 1 | K19: 1 | L19: 1 | M19: 1 | N19: 2 | O19: 2 | P19: 2 | Q19: 2 | R19: 3 | S19: 3 | T19: 3 | U19: 3 | V19: 2 | W19: 2 | X19: 2 | Y19: 2 | AB19: 2 | AC19: 2 | AF19: 1 | AG19: 1 | AH19: 2 | AI19: 2 | AJ19: 2 | AK19: 2 | AL19: 1 | AM19: 1 | AN19: 1 | AO19: 1 | AP19: 1 | AQ19: 1 | AR19: 1 | AS19: 1
C20: Drainage (Time : min) | D20: LEV-1 | E20: 2 min | F20: 0.0013888889 | G20: 0.0013888889 | H20: 0.0013888889 | I20: 0.0013888889 | J20: 0.0013888889 | K20: 0.0013888889 | L20: 0.0013888889 | M20: 0.0013888889 | N20: 0.0013888889 | O20: 0.0013888889 | P20: 0.0013888889 | Q20: 0.0013888889 | R20: 0.0013888889 | S20: 0.0013888889 | T20: 0.0013888889 | U20: 0.0013888889 | V20: 0.0013888889 | W20: 0.0013888889 | X20: 0.0013888889 | Y20: 0.0013888889 | AB20: 0.0013888889 | AC20: 0.0013888889 | AF20: 0.0013888889 | AG20: 0.0013888889 | AH20: 0.0013888889 | AI20: 0.0013888889 | AJ20: 0.0013888889 | AK20: 0.0013888889 | AL20: 0.0013888889 | AM20: 0.0013888889 | AN20: 0.0013888889 | AO20: 0.0013888889 | AP20: 0.0013888889 | AQ20: 0.0013888889 | AR20: 0.0013888889 | AS20: 0.0013888889
D21: LEV-2
D22: LEV-3
D23: LEV-4
C24: Balance Spin | D24: _ | E24: 180 sec | F24: 0.0020833333 | G24: 0.0020833333 | H24: 0.0020833333 | I24: 0.0020833333 | J24: 0.0020833333 | K24: 0.0020833333 | L24: 0.0020833333 | M24: 0.0020833333 | N24: 0.0020833333 | O24: 0.0020833333 | P24: 0.0020833333 | Q24: 0.0020833333 | R24: 0.0020833333 | S24: 0.0020833333 | T24: 0.0020833333 | U24: 0.0020833333 | V24: 0.0020833333 | W24: 0.0020833333 | X24: 0.0020833333 | Y24: 0.0020833333 | AB24: 0.0017939815 | AC24: 0.0017939815 | AF24: 0.0017939815 | AG24: 0.0017939815 | AH24: 0.0020833333 | AI24: 0.0020833333 | AJ24: 0.0020833333 | AK24: 0.0020833333 | AL24: 0.0020833333 | AM24: 0.0020833333 | AN24: 0.0020833333 | AO24: 0.0020833333 | AP24: 0.0017939815 | AQ24: 0.0017939815 | AR24: 0.0017939815 | AS24: 0.0017939815
D25: _ | E25: 155 sec
C26: Medium Spin (Time : sec) | D26: _ | E26: 20 sec | F26: 0.0013888889 | G26: 0.0013888889 | H26: 0.0013888889 | I26: 0.0013888889 | J26: 0.00046296296 | K26: 0.00046296296 | L26: 0.00046296296 | M26: 0.00046296296 | N26: 0.0013888889 | O26: 0.0013888889 | P26: 0.0013888889 | Q26: 0.0013888889 | R26: 0.0013888889 | S26: 0.0013888889 | T26: 0.0013888889 | U26: 0.0013888889 | V26: 0.0013888889 | W26: 0.0013888889 | X26: 0.0013888889 | Y26: 0.0013888889 | AB26: 0.00046296296 | AC26: 0.00046296296 | AF26: 0.00023148148 | AG26: 0.00023148148 | AH26: 0.0013888889 | AI26: 0.0013888889 | AJ26: 0.0013888889 | AK26: 0.0013888889 | AL26: 0.0013888889 | AM26: 0.0013888889 | AN26: 0.0013888889 | AO26: 0.0013888889 | AP26: 0.00046296296 | AQ26: 0.00046296296 | AR26: 0.00046296296 | AS26: 0.00046296296
D27: _ | E27: 40 sec
D28: _ | E28: 120 sec
C29: Inertia Stop (Time : sec) | D29: _ | E29: 60 sec | F29: 0.00069444444 | G29: 0.00069444444 | H29: 0.00069444444 | I29: 0.00069444444 | J29: 0.00069444444 | K29: 0.00069444444 | L29: 0.00069444444 | M29: 0.00069444444 | N29: 0.00069444444 | O29: 0.00069444444 | P29: 0.00069444444 | Q29: 0.00069444444 | R29: 0.00069444444 | S29: 0.00069444444 | T29: 0.00069444444 | U29: 0.00069444444 | V29: 0.00069444444 | W29: 0.00069444444 | X29: 0.00069444444 | Y29: 0.00069444444 | AB29: 0.00069444444 | AC29: 0.00069444444 | AF29: 0.00069444444 | AG29: 0.00069444444 | AH29: 0.00069444444 | AI29: 0.00069444444 | AJ29: 0.00069444444 | AK29: 0.00069444444 | AL29: 0.00069444444 | AM29: 0.00069444444 | AN29: 0.00069444444 | AO29: 0.00069444444 | AP29: 0.00069444444 | AQ29: 0.00069444444 | AR29: 0.00069444444 | AS29: 0.00069444444
C30: Water Filling (Time : min) | D30: LEV-1 | E30: 3 min | F30: 0.0020833333 | G30: 0.0027777778 | H30: 0.0034722222 | I30: 0.0041666667 | J30: 0.0020833333 | K30: 0.0027777778 | L30: 0.0034722222 | M30: 0.0041666667 | N30: 0.0020833333 | O30: 0.0027777778 | P30: 0.0034722222 | Q30: 0.0041666667 | R30: 0.0020833333 | S30: 0.0027777778 | T30: 0.0034722222 | U30: 0.0041666667 | V30: 0.0020833333 | W30: 0.0027777778 | X30: 0.0034722222 | Y30: 0.0041666667 | AB30: 0.0034722222 | AC30: 0.0041666667 | AF30: 0.0034722222 | AG30: 0.0041666667 | AH30: 0.0020833333 | AI30: 0.0027777778 | AJ30: 0.0034722222 | AK30: 0.0041666667 | AL30: 0.0020833333 | AM30: 0.0027777778 | AN30: 0.0034722222 | AO30: 0.0041666667 | AP30: 0.0020833333 | AQ30: 0.0027777778 | AR30: 0.0034722222 | AS30: 0.0041666667
D31: LEV-2 | E31: 4 min
D32: LEV-3 | E32: 5 min
D33: LEV-4 | E33: 6 min
C34: Rinse Wash (Time : min) | D34: _ | E34: 2 min | F34: 0.0027777778 | G34: 0.0027777778 | H34: 0.0027777778 | I34: 0.0027777778 | J34: 0.0020833333 | K34: 0.0020833333 | L34: 0.0020833333 | M34: 0.0020833333 | N34: 0.0027777778 | O34: 0.0027777778 | P34: 0.0027777778 | Q34: 0.0027777778 | R34: 0.0027777778 | S34: 0.0027777778 | T34: 0.0027777778 | U34: 0.0027777778 | V34: 0.0027777778 | W34: 0.0027777778 | X34: 0.0027777778 | Y34: 0.0027777778 | AB34: 0.0013888889 | AC34: 0.0013888889 | AF34: 0.0013888889 | AG34: 0.0013888889 | AH34: 0.0027777778 | AI34: 0.0027777778 | AJ34: 0.0027777778 | AK34: 0.0027777778 | AL34: 0.0013888889 | AM34: 0.0013888889 | AN34: 0.0013888889 | AO34: 0.0013888889 | AP34: 0.0013888889 | AQ34: 0.0013888889 | AR34: 0.0013888889 | AS34: 0.0013888889
D35: _ | E35: 3 min
D36: _ | E36: 4 min
C37: Rinse Time (min) | F37: =((F26+F24+F29)+F30+F34+F20)*F19 -> 0.020833333 | G37: =((G24+G26+G29)+G20+G30+G34)*G19 -> 0.022222222 | H37: =((H24+H26+H29)+H20+H30+H34)*H19 -> 0.023611111 | I37: =((I24+I26+I29)+I20+I30+I34)*I19 -> 0.025 | J37: =((J26+J24+J29)+J30+J34+J20)*J19 -> 0.0087962963 | K37: =((K24+K26+K29)+K20+K30+K34)*K19 -> 0.0094907407 | L37: =((L24+L26+L29)+L20+L30+L34)*L19 -> 0.010185185 | M37: =((M24+M26+M29)+M20+M30+M34)*M19 -> 0.01087963 | N37: =((N26+N24+N29)+N30+N34+N20)*N19 -> 0.020833333 | O37: =((O24+O26+O29)+O20+O30+O34)*O19 -> 0.022222222 | P37: =((P24+P26+P29)+P20+P30+P34)*P19 -> 0.023611111 | Q37: =((Q24+Q26+Q29)+Q20+Q30+Q34)*Q19 -> 0.025 | R37: =((R26+R24+R29)+R30+R34+R20)*R19 -> 0.03125 | S37: =((S24+S26+S29)+S20+S30+S34)*S19 -> 0.033333333 | T37: =((T24+T26+T29)+T20+T30+T34)*T19 -> 0.035416667 | U37: =((U24+U26+U29)+U20+U30+U34)*U19 -> 0.0375 | V37: =((V26+V24+V29)+V30+V34+V20)*V19 -> 0.020833333 | W37: =((W24+W26+W29)+W20+W30+W34)*W19 -> 0.022222222 | X37: =((X24+X26+X29)+X20+X30+X34)*X19 -> 0.023611111 | Y37: =((Y24+Y26+Y29)+Y20+Y30+Y34)*Y19 -> 0.025 | AB37: =((AB24+AB26+AB29)+AB20+AB30+AB34)*AB19 -> 0.018402778 | AC37: =((AC24+AC26+AC29)+AC20+AC30+AC34)*AC19 -> 0.019791667 | AF37: =((AF24+AF26+AF29)+AF20+AF30+AF34)*AF19 -> 0.0089699074 | AG37: =((AG24+AG26+AG29)+AG20+AG30+AG34)*AG19 -> 0.0096643519 | AH37: =((AH26+AH24+AH29)+AH30+AH34+AH20)*AH19 -> 0.020833333 | AI37: =((AI24+AI26+AI29)+AI20+AI30+AI34)*AI19 -> 0.022222222 | AJ37: =((AJ24+AJ26+AJ29)+AJ20+AJ30+AJ34)*AJ19 -> 0.023611111 | AK37: =((AK24+AK26+AK29)+AK20+AK30+AK34)*AK19 -> 0.025 | AL37: =((AL26+AL24+AL29)+AL30+AL34+AL20)*AL19 -> 0.0090277778 | AM37: =((AM24+AM26+AM29)+AM20+AM30+AM34)*AM19 -> 0.0097222222 | AN37: =((AN24+AN26+AN29)+AN20+AN30+AN34)*AN19 -> 0.010416667 | AO37: =((AO24+AO26+AO29)+AO20+AO30+AO34)*AO19 -> 0.011111111 | AP37: =((AP26+AP24+AP29)+AP30+AP34+AP20)*AP19 -> 0.0078125 | AQ37: =((AQ24+AQ26+AQ29)+AQ20+AQ30+AQ34)*AQ19 -> 0.0085069444 | AR37: =((AR24+AR26+AR29)+AR20+AR30+AR34)*AR19 -> 0.0092013889 | AS37: =((AS24+AS26+AS29)+AS20+AS30+AS34)*AS19 -> 0.0098958333
B38: Spin | C38: Drainage (Time : min) | D38: LEV-1 | E38: 2 min | F38: 0.0013888889 | G38: 0.0013888889 | H38: 0.0013888889 | I38: 0.0013888889 | J38: 0.0013888889 | K38: 0.0013888889 | L38: 0.0013888889 | M38: 0.0013888889 | N38: 0.0013888889 | O38: 0.0013888889 | P38: 0.0013888889 | Q38: 0.0013888889 | R38: 0.0013888889 | S38: 0.0013888889 | T38: 0.0013888889 | U38: 0.0013888889 | V38: 0.0013888889 | W38: 0.0013888889 | X38: 0.0013888889 | Y38: 0.0013888889 | AB38: 0.0013888889 | AC38: 0.0013888889 | AF38: 0.0013888889 | AG38: 0.0013888889 | AH38: 0.0013888889 | AI38: 0.0013888889 | AJ38: 0.0013888889 | AK38: 0.0013888889 | AL38: 0.0013888889 | AM38: 0.0013888889 | AN38: 0.0013888889 | AO38: 0.0013888889 | AP38: 0.0013888889 | AQ38: 0.0013888889 | AR38: 0.0013888889 | AS38: 0.0013888889
D39: LEV-2
D40: LEV-3
...

Sheet Water Levels
B3: Sharp VE BLDC 11/13kg
B5: Display Water Level | C5: Water Amount (L) | D5: Load (kg)
B6: 1 | C6: 28 | D6: 0_2 | F6: y = 21.6x + 6.5
B7: 2 | C7: 50 | D7: 3_5
B8: 3 | C8: 71 | D8: 6_8 | E8: 1 | F8: =21.6*E8+6.5 -> 28.1
B9: 4 | C9: 93 | D9: 9_13 | E9: 2 | F9: =21.6*E9+6.5 -> 49.7
E10: 3 | F10: =21.6*E10+6.5 -> 71.3
E11: 4 | F11: =21.6*E11+6.5 -> 92.9

Sheet Course Group 1
B2: For Regular, Quick, Baby Care & Quick Rinse Courses
B3: Note: For Quick course only, skip M2 & M3
B5: Sharp VE BLDC 11/13kg
B7: Internal Levels | C7: Load (Kg) | D7: Water Level Display | E7: Total Wash Time without Filling Time | F7: M1 Motion + Water Filling | L7: M2 Motion | Q7: M3 Motion | W7: M4 Motion | AC7: WL Check | AD7: M5 Motion | AI7: M6 Motion | AN7: M7 Motion | AS7: MU Motion | AX7: Stop | AY7: MU Motion
F8: Water level @ M1 Start | G8: CW | H8: Stop Time | I8: CCW | J8: Stop Time | K8: 1st Water Supply End M1 End | L8: CW | M8: Stop Time | N8: CCW | O8: Stop Time | P8: Subtotal Time | Q8: 2nd Water Supply | R8: CW | S8: Stop Time | T8: CCW | U8: Stop Time | V8: Subtotal Time | W8: 3rd Water Supply. | X8: CW | Y8: Stop Time | Z8: CCW | AA8: Stop Time | AB8: Subtotal Time | AD8: CW | AE8: Stop Time | AF8: CCW | AG8: Stop Time | AH8: Subtotal Time | AI8: CW | AJ8: Stop Time | AK8: CCW | AL8: Stop Time | AM8: Subtotal Time | AN8: CW | AO8: Stop Time | AP8: CCW | AQ8: Stop Time | AR8: Subtotal Time | AS8: CW | AT8: Stop Time | AU8: CCW | AV8: Stop Time | AW8: Subtotal Time | AY8: CW | AZ8: Stop Time | BA8: CCW | BB8: Stop Time | BC8: Subtotal Time
B9: 1 | C9: ='Water Levels'!D6 -> 0_2 | D9: 1 | E9: =SUM(P9+V9+AB9+AH9+AM9+AR9+AW9+BC9)/60 -> 17 | K9: =W9 -> 28 | L9: 0.5 | M9: 1 | N9: 0.5 | O9: 1 | P9: 60 | Q9: =W9 -> 28 | R9: 0.7 | S9: 1 | T9: 0.7 | U9: 1 | V9: 180 | W9: ='Water Levels'!C6 -> 28 | X9: 0.6 | Y9: 1 | Z9: 0.6 | AA9: 1 | AB9: 720 | AY9: 0.3 | AZ9: 0.7 | BA9: 0.3 | BB9: 0.7 | BC9: 60
B10: 2 | C10: ='Water Levels'!D7 -> 3_5 | D10: 2 | E10: =SUM(P10+V10+AB10+AH10+AM10+AR10+AW10+BC10)/60 -> 18 | K10: =W10 -> 50 | L10: 0.8 | M10: 1 | N10: 0.8 | O10: 1 | P10: 60 | Q10: =W10 -> 50 | R10: 2.1 | S10: 1 | T10: 2.1 | U10: 1 | V10: 180 | W10: ='Water Levels'!C7 -> 50 | X10: 0.9 | Y10: 1 | Z10: 0.9 | AA10: 1 | AB10: 720 | AY10: 0.3 | AZ10: 0.7 | BA10: 0.3 | BB10: 0.7 | BC10: 120
B11: 3 | C11: ='Water Levels'!D8 -> 6_8 | D11: 3 | E11: =SUM(P11+V11+AB11+AH11+AM11+AR11+AW11+BC11)/60 -> 17 | K11: =W11 -> 71 | L11: 1.3 | M11: 1 | N11: 1.3 | O11: 1 | P11: 60 | Q11: =W11 -> 71 | R11: 1.2 | S11: 1 | T11: 1.2 | U11: 1 | V11: 180 | W11: ='Water Levels'!C8 -> 71 | X11: 1.1 | Y11: 1 | Z11: 1.1 | AA11: 1 | AB11: 720 | AY11: 0.3 | AZ11: 0.5 | BA11: 0.3 | BB11: 0.5 | BC11: 60
B12: 4 | C12: ='Water Levels'!D9 -> 9_13 | D12: 4 | E12: =SUM(P12+V12+AB12+AH12+AM12+AR12+AW12+BC12)/60 -> 18 | K12: =W12 -> 93 | L12: 1.5 | M12: 1 | N12: 1.5 | O12: 1 | P12: 60 | Q12: =W12 -> 93 | R12: 1.8 | S12: 1.5 | T12: 1.8 | U12: 1.5 | V12: 180 | W12: ='Water Levels'!C9 -> 93 | X12: 2.2 | Y12: 1.5 | Z12: 2.2 | AA12: 1.5 | AB12: 720 | AY12: 0.3 | AZ12: 0.5 | BA12: 0.3 | BB12: 0.5 | BC12: 120
F17: M1 start at 110L | L17: M2 start when the 1st w.s end | R17: Input | S17: M2 End (time 60 sec) | X17: Input | Y17: M3 End + 2nd W.S Target | AD17: Input | AE17: M4 End + Target W.L Check
C18: Not included | F18: Motion end when 1st W.S end or after 120 sec. | L18: Motion continues for 60 sec | R18: Output | S18: 2nd W.L Target & M3 time | X18: Output | Y18: M4 Time + 3rd W.S target | AD18: Output | AE18: M5 Motion time
C19: Motion time depends on selection | F19: Water fill continues till arriving the 1st w.s end level | L19: Water valve is closed | R19: Process | S19: Start | T19: End | X19: Process | Y19: Start | AA19: End | AD19: Process | AE19: Start | AF19: End | AI19: Same as Process M5 | AN19: Same as Process M5 | AS19: Same as Process M5 | AY19: Same as Process M5
C20: Data linked to another sheet | R20: Pulsator | S20: M2 End | T20: M3 Time + 2nd W.S Target | X20: Pulsator | Y20: M3 End + 2nd W.S Target | AA20: M4 time + 3rd W.S Target | AD20: Pulsator | AE20: M4 End | AF20: M5 Time
L21: * Total time start with M2 | R21: Valve | S21: Target Water Level | X21: Valve | Y21: Target Water Level | AD21: Valve | AE21: Closed
AC23: These Processes are repeated 3 Times
L29: =#REF!-L9 -> #REF! | M29: =#REF!-M9 -> #REF! | N29: =#REF!-N9 -> #REF! | O29: =#REF!-O9 -> #REF! | P29: =#REF!-P9 -> #REF! | Q29: =#REF!-Q9 -> #REF! | R29: =#REF!-R9 -> #REF! | S29: =#REF!-S9 -> #REF! | ... BC29: =#REF!-BC9 -> #REF!
L30: =#REF!-L10 -> #REF! | M30: =#REF!-M10 -> #REF! | N30: =#REF!-N10 -> #REF! | O30: =#REF!-O10 -> #REF! | P30: =#REF!-P10 -> #REF! | Q30: =#REF!-Q10 -> #REF! | R30: =#REF!-R10 -> #REF! | S30: =#REF!-S10 -> #REF! | ... BC30: =#REF!-BC10 -> #REF!
L31: =#REF!-L11 -> #REF! | M31: =#REF!-M11 -> #REF! | N31: =#REF!-N11 -> #REF! | O31: =#REF!-O11 -> #REF! | P31: =#REF!-P11 -> #REF! | Q31: =#REF!-Q11 -> #REF! | R31: =#REF!-R11 -> #REF! | S31: =#REF!-S11 -> #REF! | ... BC31: =#REF!-BC11 -> #REF!
L32: =#REF!-L12 -> #REF! | M32: =#REF!-M12 -> #REF! | N32: =#REF!-N12 -> #REF! | O32: =#REF!-O12 -> #REF! | P32: =#REF!-P12 -> #REF! | Q32: =#REF!-Q12 -> #REF! | R32: =#REF!-R12 -> #REF! | S32: =#REF!-S12 -> #REF! | ... BC32: =#REF!-BC12 -> #REF!

Sheet Course Group 2
B2: For Jeans, Cotton & Heavy Courses
B4: Sharp VE BLDC 11/13kg
B6: Internal Levels | C6: Load (Kg) | D6: Water Level Display | E6: Total Wash Time without Filling Time | F6: M1 Motion + Water Filling | L6: M2 Motion | Q6: M3 Motion | W6: M4 Motion | AC6: WL Check | AD6: M5 Motion | AI6: M6 Motion | AN6: M7 Motion | AS6: MU Motion | AX6: Stop | AY6: MU Motion
F7: Water level @ M1 Start | G7: CW | H7: Stop Time | I7: CCW | J7: Stop Time | K7: 1st Water Supply End M1 End | L7: CW | M7: Stop Time | N7: CCW | O7: Stop Time | P7: Subtotal Time | Q7: 2nd Water Supply | R7: CW | S7: Stop Time | T7: CCW | U7: Stop Time | V7: Subtotal Time | W7: 3rd Water Supply | X7: CW | Y7: Stop Time | Z7: CCW | AA7: Stop Time | AB7: Subtotal Time | AD7: CW | AE7: Stop Time | AF7: CCW | AG7: Stop Time | AH7: Subtotal Time | AI7: CW | AJ7: Stop Time | AK7: CCW | AL7: Stop Time | AM7: Subtotal Time | AN7: CW | AO7: Stop Time | AP7: CCW | AQ7: Stop Time | AR7: Subtotal Time | AS7: CW | AT7: Stop Time | AU7: CCW | AV7: Stop Time | AW7: Subtotal Time | AY7: CW | AZ7: Stop Time | BA7: CCW | BB7: Stop Time | BC7: Subtotal Time
B8: 1 | C8: ='Water Levels'!D6 -> 0_2 | D8: 1 | E8: =SUM(P8+V8+AB8+AH8+AM8+AR8+AW8+BC8)/60 -> 17 | K8: =W8 -> 28 | L8: 0.7 | M8: 1 | N8: 0.7 | O8: 1 | P8: 60 | Q8: =W8 -> 28 | R8: 0.7 | S8: 1 | T8: 0.7 | U8: 1 | V8: 180 | W8: ='Water Levels'!C6 -> 28 | X8: 0.7 | Y8: 1 | Z8: 0.7 | AA8: 1 | AB8: 720 | AY8: 0.3 | AZ8: 0.7 | BA8: 0.3 | BB8: 0.7 | BC8: 60
B9: 2 | C9: ='Water Levels'!D7 -> 3_5 | D9: 2 | E9: =SUM(P9+V9+AB9+AH9+AM9+AR9+AW9+BC9)/60 -> 17 | K9: =W9 -> 50 | L9: 1 | M9: 1 | N9: 1 | O9: 1 | P9: 60 | Q9: =W9 -> 50 | R9: 1 | S9: 1 | T9: 1 | U9: 1 | V9: 180 | W9: ='Water Levels'!C7 -> 50 | X9: 1 | Y9: 1 | Z9: 1 | AA9: 1 | AB9: 720 | AY9: 0.3 | AZ9: 0.7 | BA9: 0.3 | BB9: 0.7 | BC9: 60
B10: 3 | C10: ='Water Levels'!D8 -> 6_8 | D10: 3 | E10: =SUM(P10+V10+AB10+AH10+AM10+AR10+AW10+BC10)/60 -> 17 | K10: =W10 -> 71 | L10: 1.2 | M10: 1 | N10: 1.2 | O10: 1 | P10: 60 | Q10: =W10 -> 71 | R10: 1.2 | S10: 1 | T10: 1.2 | U10: 1 | V10: 180 | W10: ='Water Levels'!C8 -> 71 | X10: 1.2 | Y10: 1 | Z10: 1.2 | AA10: 1 | AB10: 720 | AY10: 0.3 | AZ10: 0.5 | BA10: 0.3 | BB10: 0.5 | BC10: 60
B11: 4 | C11: ='Water Levels'!D9 -> 9_13 | D11: 4 | E11: =SUM(P11+V11+AB11+AH11+AM11+AR11+AW11+BC11)/60 -> 18 | K11: =W11 -> 93 | L11: 1.8 | M11: 1 | N11: 1.8 | O11: 1 | P11: 60 | Q11: =W11 -> 93 | R11: 2.1 | S11: 1.5 | T11: 2.1 | U11: 1.5 | V11: 180 | W11: ='Water Levels'!C9 -> 93 | X11: 2.5 | Y11: 2 | Z11: 2.5 | AA11: 2 | AB11: 720 | AY11: 0.3 | AZ11: 0.5 | BA11: 0.3 | BB11: 0.5 | BC11: 120
R13: 1.8 | T13: 1.8
G16: M1 start at 110L | L16: M2 start when the 1st w.s end | R16: Input | S16: M2 End (time 60 sec) | X16: Input | Y16: M3 End + 2nd W.S Target | AD16: Input | AE16: M4 End + Target W.L Check
C17: Not included | G17: Motion end when 1st W.S end or after 120 sec. | L17: Motion continues for 60 sec | R17: Output | S17: 2nd W.L Target & M3 time | X17: Output | Y17: M4 Time + 3rd W.S target | AD17: Output | AE17: M5 Motion time
C18: Motion time depends on selection | G18: Water fill continues till arriving the 1st w.s end level | L18: Water valve is closed | R18: Process | S18: Start | T18: End | W18: Process | X18: Start | AA18: End | AE18: Start | AG18: End | AI18: Same as Process M5 | AN18: Same as Process M5 | AS18: Same as Process M5 | AY18: Same as Process M5
C19: Data linked to another sheet | R19: Pulsator | S19: M2 End | T19: M3 Time + 2nd W.S Target | W19: Pulsator | X19: M3 End + 2nd W.S Target | AA19: St time + 3rd W.S Target | AE19: M4 End + Target W.L Check | AG19: M5 Time
L20: * Total time start with M2 | R20: Valve | S20: Target Water Level | W20: Valve | X20: Target Water Level | AE20: Closed
AC22: These Processes are repeated 3 Times
L30: =#REF!-L8 -> #REF! | M30: =#REF!-M8 -> #REF! | N30: =#REF!-N8 -> #REF! | O30: =#REF!-O8 -> #REF! | P30: =#REF!-P8 -> #REF! | Q30: =#REF!-Q8 -> #REF! | R30: =#REF!-R8 -> #REF! | S30: =#REF!-S8 -> #REF! | ... BC30: =#REF!-BC8 -> #REF!
L31: =#REF!-L9 -> #REF! | M31: =#REF!-M9 -> #REF! | N31: =#REF!-N9 -> #REF! | O31: =#REF!-O9 -> #REF! | P31: =#REF!-P9 -> #REF! | Q31: =#REF!-Q9 -> #REF! | R31: =#REF!-R9 -> #REF! | S31: =#REF!-S9 -> #REF! | ... BC31: =#REF!-BC9 -> #REF!
L32: =#REF!-L10 -> #REF! | M32: =#REF!-M10 -> #REF! | N32: =#REF!-N10 -> #REF! | O32: =#REF!-O10 -> #REF! | P32: =#REF!-P10 -> #REF! | Q32: =#REF!-Q10 -> #REF! | R32: =#REF!-R10 -> #REF! | S32: =#REF!-S10 -> #REF! | ... BC32: =#REF!-BC10 -> #REF!
L33: =#REF!-L11 -> #REF! | M33: =#REF!-M11 -> #REF! | N33: =#REF!-N11 -> #REF! | O33: =#REF!-O11 -> #REF! | P33: =#REF!-P11 -> #REF! | Q33: =#REF!-Q11 -> #REF! | R33: =#REF!-R11 -> #REF! | S33: =#REF!-S11 -> #REF! | ... BC33: =#REF!-BC11 -> #REF!

Sheet Course Group 3
B2: For Wool, Delicate & Sports Wear Courses
B4: Sharp VE BLDC 11/13kg
B6: Internal Levels | C6: Load (Kg) | D6: Water Level Display | E6: Total Wash Time without Filling Time | F6: M1 Motion + Water Filling | L6: M2 Motion | Q6: M3 Motion | W6: M4 Motion | AC6: WL Check | AD6: M5 Motion | AI6: M6 Motion | AN6: M7 Motion | AS6: MU Motion | AX6: Stop | AY6: MU Motion
F7: Water level @ M1 Start | G7: CW | H7: Stop Time | I7: CCW | J7: Stop Time | K7: 1st Water Supply End M1 End | L7: CW | M7: Stop Time | N7: CCW | O7: Stop Time | P7: Subtotal Time | Q7: 2nd Water Supply | R7: CW | S7: Stop Time | T7: CCW | U7: Stop Time | V7: Subtotal Time | W7: 3rd Water Supply | X7: CW | Y7: Stop Time | Z7: CCW | AA7: Stop Time | AB7: Subtotal Time | AD7: CW | AE7: Stop Time | AF7: CCW | AG7: Stop Time | AH7: Subtotal Time | AI7: CW | AJ7: Stop Time | AK7: CCW | AL7: Stop Time | AM7: Subtotal Time | AN7: CW | AO7: Stop Time | AP7: CCW | AQ7: Stop Time | AR7: Subtotal Time | AS7: CW | AT7: Stop Time | AU7: CCW | AV7: Stop Time | AW7: Subtotal Time | AY7: CW | AZ7: Stop Time | BA7: CCW | BB7: Stop Time | BC7: Subtotal Time
B8: 1 | C8: ='Water Levels'!D6 -> 0_2 | D8: 1 | E8: =SUM(P8+V8+AB8+AH8+AM8+AR8+AW8+BC8)/60 -> 13 | K8: =Q8 -> 28 | L8: 0.5 | M8: 2 | N8: 0.5 | O8: 2 | P8: 60 | Q8: =W8 -> 28 | R8: 0.5 | S8: 2 | T8: 0.5 | U8: 2 | V8: 180 | W8: ='Water Levels'!C6 -> 28 | X8: 0.5 | Y8: 2 | Z8: 0.5 | AA8: 2 | AB8: 540
B9: 2 | C9: ='Water Levels'!D7 -> 3_5 | D9: 2 | E9: =SUM(P9+V9+AB9+AH9+AM9+AR9+AW9+BC9)/60 -> 13 | K9: =Q9 -> 50 | L9: 0.5 | M9: 2 | N9: 0.5 | O9: 2 | P9: 60 | Q9: =W9 -> 50 | R9: 0.5 | S9: 2 | T9: 0.5 | U9: 2 | V9: 180 | W9: ='Water Levels'!C7 -> 50 | X9: 0.5 | Y9: 2 | Z9: 0.5 | AA9: 2 | AB9: 540
B10: 3 | C10: ='Water Levels'!D8 -> 6_8 | D10: 3 | E10: =SUM(P10+V10+AB10+AH10+AM10+AR10+AW10+BC10)/60 -> 13 | K10: =Q10 -> 71 | L10: 0.5 | M10: 2 | N10: 0.5 | O10: 2 | P10: 60 | Q10: =W10 -> 71 | R10: 0.5 | S10: 2 | T10: 0.5 | U10: 2 | V10: 180 | W10: ='Water Levels'!C8 -> 71 | X10: 0.5 | Y10: 2 | Z10: 0.5 | AA10: 2 | AB10: 540
B11: 4 | C11: ='Water Levels'!D9 -> 9_13 | D11: 4 | E11: =SUM(P11+V11+AB11+AH11+AM11+AR11+AW11+BC11)/60 -> 13 | K11: =Q11 -> 93 | L11: 0.5 | M11: 2 | N11: 0.5 | O11: 2 | P11: 60 | Q11: =W11 -> 93 | R11: 0.5 | S11: 2 | T11: 0.5 | U11: 2 | V11: 180 | W11: ='Water Levels'!C9 -> 93 | X11: 0.5 | Y11: 2 | Z11: 0.5 | AA11: 2 | AB11: 540
G16: M1 start at 110L | L16: M2 start when the 1st w.s end | R16: Input | S16: M2 End (time 60 sec) | X16: Input | Y16: M3 End + 2nd W.S Target | AD16: Input | AE16: M4 End + Target W.L Check
C17: Not included | G17: Motion end when 1st W.S end or after 120 sec. | L17: Motion continues for 60 sec | R17: Output | S17: 2nd W.L Target & M3 time | X17: Output | Y17: M4 Time + 3rd W.S target | AD17: Output | AE17: M5 Motion time
C18: Motion time depends on selection | G18: Water fill continues till arriving the 1st w.s end level | L18: Water valve is closed | R18: Process | S18: Start | T18: End | W18: Process | X18: Start | AA18: End | AE18: Start | AG18: End | AI18: Same as Process M5 | AN18: Same as Process M5 | AS18: Same as Process M5 | AY18: Same as Process M5
C19: Data linked to another sheet | R19: Pulsator | S19: M2 End | T19: M3 Time + 2nd W.S Target | W19: Pulsator | X19: M3 End + 2nd W.S Target | AA19: M4 time + 3rd W.S Target | AE19: M4 End + Target W.L Check | AG19: M5 Time
L20: * Total time start with M2 | R20: Valve | S20: Target Water Level | W20: Valve | X20: Target Water Level | AE20: Closed
AC22: These Processes are repeated 3 Times

Sheet Tub Clean
B2: Sharp VE BLDC 11/13kg
B4: Water Supply and Stiring | N4: Soak | S4: Wash | X4: Clutch Switch (Drain Water) | Y4: 1st Spin | AB4: 2nd Spin | AF4: Clutch Switch | AG4: Water Supply with Stiring | AL4: Wash | AQ4: Clutch Switch (Drain Water) | AR4: 3rd Spin | AU4: 4th Spin
B5: Water Supply (L) | C5: Stirring motion | H5: Water Supply (L) | I5: Stirring | J5: Water Supply (L) | K5: Stirring | L5: Water Supply (L) | M5: Stirring | N5: after reaching 4th water level (60ON－240OFF) | AG5: Stire with supply water in order from the lowest water level | AU5: Drain valve is open
C6: CW | D6: Stop Time | E6: CCW | F6: Stop Time | G6: Total Time | N6: CW | O6: Stop Time | P6: CCW | Q6: Stop Time | R6: Total Time | S6: CW | T6: Stop Time | U6: CCW | V6: Stop Time | W6: Total Time | Y6: Motor | AA6: Break | AB6: Drain Water | AC6: Motor | AE6: Break | AG6: CW | AH6: Stop Time | AI6: CCW | AJ6: Stop Time | AK6: Total Time | AL6: CW | AM6: Stop Time | AN6: CCW | AO6: Stop Time | AP6: Total Time | AR6: Motor | AT6: Break | AU6: Drain Water | AV6: Motor | AX6: Break
Y7: rpm | Z7: ON | AC7: rpm | AD7: ON | AR7: rpm | AS7: ON | AV7: rpm | AW7: ON
B8: ='Water Levels'!C6 -> 28 | C8: 3.4 | D8: 4.6 | E8: 3.4 | F8: 4.6 | G8: 120 | H8: ='Water Levels'!C7 -> 50 | I8: Same as first Stirring | J8: ='Water Levels'!C8 -> 71 | K8: Same as first Stirring | L8: ='Water Levels'!C9 -> 93 | M8: Same as first Stirring | N8: 1.5 | O8: 1 | P8: 1.5 | Q8: 1 | R8: 20 | S8: 1.5 | T8: 1 | U8: 1.5 | V8: 1 | W8: 180 | Y8: Top 70 rpm 10 rpm / s | Z8: 30 | AA8: After stop detection , shift next process (MAX 30") | AB8: After reaching Reset Water Level | AC8: Top 700 rpm | AD8: 100 | AE8: After stop detection , shift next process (MAX 30) | AG8: Same as water supply with stiring specs | AL8: 1.5 | AM8: 1 | AN8: 1.5 | AO8: 1 | AP8: 3 | AR8: Top 70 rpm 10 rpm / s | AS8: 30 | AT8: After stop detection , shift next process (MAX 30) | AU8: After reaching Reset Water Level | AV8: Top 700 rpm | AW8: 100 | AX8: After stop detection , shift next process (MAX 30)
N9: `
C14: Clutch Confirmation Operation
B16: Specifications / Definitions
B17: Process | F17: Specifications / Definitions
B18: Water supply with stirring | F18: 1.After reaching set water level, stirring is started.
B20: Soak | F20: 1.The operation of stirring for 1 minute and stopping for 4 minutes is repeated within the set time.
B21: Whole | F21: 1. No supply water is added.
F22: 2. Reservations cannot be set.
F23: 3. The abnormality detection operation conforms to the operation during regular course operation.

Sheet Blanket
B2: All times in sec
B3: Capacity | C3: Water Level | D3: Water amout | E3: Water Supply with Stiring | J3: Wash Process | T3: 1st Spin | X3: Static Rinse S | Y3: 2nd Spin | AC3: Static Rinse S 3 times Setting | AD3: 3rd Spin | AH3: Static Rinse W * Water Supply is started after drain valve closes | AS3: Final Spin
J4: Wash | O4: Untangle
E5: Finish when set water level is reached MAX 300 | T5: Drain Water and Clutch Change | U5: Spin 1 | W5: Normal Short Break | Y5: Drain Water and Clutch Change | Z5: Internal Spin | AB5: Normal Short Break | AD5: Drain Water and Clutch Change | AE5: Internal Spin | AG5: Normal Short Break | AH5: Softener inlet valve start water level | AJ5: Water Supply with Stir | AM5: Stir | AP5: Untangle | AS5: Drain Water and Clutch Change | AT5: Internal Spin | AV5: Normal Short Break
E6: Start WL | F6: CW | G6: Stop Time | H6: CCW | I6: Stop Time | J6: CW | K6: Stop Time | L6: CCW | M6: Stop Time | N6: Total Time | O6: CW | P6: Stop Time | Q6: CCW | R6: Stop Time | S6: Total Time | U6: Motor | Z6: Motor | AE6: Motor | AT6: Motor
U7: rpm | V7: ON | Z7: rpm | AA7: ON | AE7: rpm | AF7: ON | AT7: rpm | AU7: ON
B8: 3 | C8: 4 | D8: ='Water Levels'!C9 -> 93 | E8: ='Water Levels'!C8 -> 71 | F8: 2.4 | G8: 1.6 | H8: 2.4 | I8: 1.6 | J8: 3.8 | K8: 0.7 | L8: 3.8 | M8: 0.7 | N8: 710* | O8: 1 | P8: 0.7 | Q8: 1 | R8: 0.7 | S8: 10 | T8: After reaching Reset Water Level 75 | U8: Top 700 rpm | V8: 430 | W8: After stop detection , shift next process (MAX 20) | X8: Inlet valve Single Same as W | Y8: After reaching Reset Water Level 75 | Z8: Same as Final Spin spec | AA8: 430 | AB8: After stop detection , shift next process (MAX 20) | AC8: Inlet valve Single | AD8: After reaching Reset Water Level 75 | AE8: Same as Final Spin spec | AF8: 430 | AG8: After stop detection , shift next process (MAX 20) | AH8: Simultaneous with start of water supply | AJ8: Same as wash Spec | AL8: Water supply to setting water level | AM8: Same as wash Spec | AO8: 180 | AP8: Same as Untangle Spec | AR8: 10 | AS8: After reaching Reset Water Level 75 | AT8: Top 700 rpm | AU8: Based on user selection | AV8: After stop detection , shift next process (MAX 20)
E9: Clutch Confirmation Operation | O9: * Highlighted Time is changeable according to manual time setting | X9: Clutch Confirmation | AC9: Clutch Confirmation | AH9: Clutch Confirmation | AS9: Clutch Confirmation
N11: Manual Selection | P11: 18 min | R11: 1070 sec
P12: 12 min | R12: 710 sec
P13: 9 min | R13: 530 sec
P14: 3 min | R14: 170 sec

Sheet Soak
B2: Sharp VE BLDC 11/13kg
B4: Load sensing result | E4: Condensed Wash | G4: Untangle | I4: Pause | J4: Soak rotary water flow - time in sec | O4: Pause | P4: Soak Water Flow - time in sec | U4: Pause | V4: Soak rotary water flow | W4: Pause | X4: Condensed Wash | Z4: Untangle | AB4: Rinse & spin starts here if selected
B5: Load (kg) | C5: Water Level | D5: Water Amount (L) | E5: Motions | F5: Time | G5: Motions | H5: Time | J5: CW | K5: OFF | L5: CCW | M5: OFF | N5: Time | P5: CW | Q5: OFF | R5: CCW | S5: OFF | T5: Time | X5: Motions | Y5: Time | Z5: Motions | AA5: Time
B6: ='Water Levels'!D6 -> 0_2 | C6: 1 | D6: ='Water Levels'!C6 -> 28 | E6: Refer to Washing Manual Timings sheet | F6: 5 min | G6: Same as selected course untangle motion MU | H6: 60 sec | I6: 4'25'' | J6: 2.4 | K6: 2.6 | L6: 2.4 | M6: 2.6 | N6: 10 sec | O6: 4'25'' | P6: Same as M4 in selected course | T6: 60 sec | U6: 4'55'' | V6: 10' | W6: 4'55'' | X6: Same as M4 in selected course | Y6: Based on user selection | Z6: Same as selected course untangle motion (refer to washing manual sheet) | AA6: 60 sec
B7: ='Water Levels'!D7 -> 3_5 | C7: 2 | D7: ='Water Levels'!C7 -> 50
B8: ='Water Levels'!D8 -> 6_8 | C8: 3 | D8: ='Water Levels'!C8 -> 71
B9: ='Water Levels'!D9 -> 9_13 | C9: 4 | D9: ='Water Levels'!C9 -> 93
D11: Soak cycle 1 | G11: Soak Cycle 2 | H11: Soak cycles are repeated based on below table
B13: It is possible to set only the soak time.
C15: Setting | E15: Pause-Rotating water flow-Pause-Soak water flow | J15: Pause-Rotating water flow-Pause
C16: 1H | E16: 5 times | J16: 1 time
C17: 2H | E17: 11 times | J17: 1 time
C18: 4H | E18: 11 times | J18: 1 time | P18: Pause＋ 5min*
P19: *for 4H setting only: add 5min to every pause period
C20: Soak is not allowed to be set if wash is not selected

Sheet Rinse
B2: Sharp VE BLDC 11/13kg
C3: if wash=0 rinse starts here
B5: Process | E5: Drain Water | F5: 1st Spin | I5: Static rinse S - 2&3 times setting | J5: Drain Water | K5: 2nd & 3rd Spin | N5: Static rinse W | V5: Drain Water | W5: Final Spin | Z5: Clutch Change | AA5: Anti-Wrinkle
E6: Darin water & Clutch Change | F6: Motor | H6: Normal short break | J6: Darin water & Clutch Change | K6: Motor | M6: Normal short break | N6: Softener valve open | O6: Stir Starting water level (L) | P6: Water supply with stir | Q6: MR Starting Water level | R6: MR | T6: Untangle | V6: Darin water & Clutch Change | W6: Motor | Y6: Normal short break | AA6: Duration (Manual Selection) | AB6: CW | AC6: OFF | AD6: CCW | AE6: OFF
B7: Capacity (kg) | C7: Water Level | D7: Water Amount (L) | F7: rpm | G7: ON Time | K7: rpm | L7: ON Time | N7: When water level is detected as below softener valve is opened (L) | R7: Stiring Motion | S7: Time | T7: Motion | U7: Time | W7: rpm | X7: ON Time | AB7: Pulsator only
B8: ='Water Levels'!D6 -> 0_2 | C8: 1 | D8: ='Water Levels'!C6 -> 28 | E8: After reaching reset water level - 150'' pause | F8: Refer to spin control | G8: Refer to sequence Chart | H8: After stop detection, shift next process 20'' | I8: Inlet Valve: Cold only (without softener) Water supply with stir - stir - untangle Same as static rinse W | J8: After reaching reset water level - 150'' pause | K8: Refer to spin control | L8: Refer to sequence Chart | M8: After stop detection, shift next process 20'' | N8: Same time as inlet valve open | O8: None | Q8: Setting Water Level | R8: same as M4 motion in selected course | S8: Refer to sequence Chart | T8: same as MU motion in selected course | U8: 60' | V8: After reaching reset water level - 150'' pause | W8: Refer to spin control | X8: Based on user selection | Y8: After stop detection, shift next process 20'' | AA8: 2 min | AB8: 0.8 | AC8: 1 | AD8: 0.8 | AE8: 1
B9: ='Water Levels'!D7 -> 3_5 | C9: 2 | D9: ='Water Levels'!C7 -> 50 | N9: Same time as inlet valve open | AB9: 0.8 | AC9: 1 | AD9: 0.8 | AE9: 1
B10: ='Water Levels'!D8 -> 6_8 | C10: 3 | D10: ='Water Levels'!C8 -> 71 | N10: =D9 -> 50 | AB10: 0.8 | AC10: 1 | AD10: 0.8 | AE10: 1
B11: ='Water Levels'!D9 -> 9_13 | C11: 4 | D11: ='Water Levels'!C9 -> 93 | N11: =D10 -> 71 | AB11: 0.8 | AC11: 1 | AD11: 0.8 | AE11: 1
N13: Input | O13: Spin Stop detection | Q13: Input | R13: Spin Stop detection | AA13: Anti-Wrinkle is not allowed to be selected if spin is not selected
N14: Output | O14: Target Water level | Q14: Output | R14: Target Water level
N15: Process | O15: Start | P15: End | Q15: Process | R15: Start | S15: End
N16: Pulsator | O16: Stir WL | P16: Target WL | Q16: Pulsator | R16: MR WL | S16: Refer to sequence Chart
N17: Water Valve | O17: Stop detection | P17: Target WL | Q17: Water Valve | R17: closed
N18: Softener valve | O18: Softener WL | P18: Target WL | Q18: Softener valve | R18: closed
D19: For course default rinse times, check course option tap
D20: Manual Selection | E20: 1 time | H20: Static Rinse W
E21: 2 time | G21: Static Rinse S | H21: Static Rinse W
E22: 3 time | F22: Static Rinse S | G22: Static Rinse S | H22: Static Rinse W
D23: Water Level if not selected | E23: 4th water level
D24: Water Temperature | E24: Cold only

Sheet Weight Detection Specs
B2: Weight detection specs:
B3: 1. when the water level is manually set, weight detection is cancelled
B4: 2. Load sensing mechanism: Using RPM sensor
B5: 3. Weight detection ON/OFF specs (milli second)
B7: CW (ON) | C7: CW (OFF) | D7: CCW (ON) | E7: CCW (OFF) | F7: Times
B8: 300 | C8: 600 | D8: 300 | E8: 600 | F8: 4 times each
B10: Start with CCW
B11: Sequence: 1 CCW then 1 CW ---> repeated
B12: Function:
B13: CW1+CCW1+CW2+CCW2+CW3+CCW3+CW4+CCW4
B15: 4. In case of water existence in tub
B16: Case1: When water is less than water level 1
B17: Weight detection is allowed
B19: Case2: When water is more than water level 1
B20: Weight detection is cancelled and 6th water level is applied
B22: Sharp VE BLDC 11/13kg
B24: 5. Border Values
B25: Lev1-2
... B29: Values will be added later

Sheet Water Inlet
B2: Sharp VE BLDC 11/13kg
B4: 1. Water Inlet During Wash
B5: Water Temp Setting | C5: Water Valves | D5: Water Level | E5: Water Amount @ Cold Valve Operation Start | F5: Water Amount @ Cold Valve Operation End | G5: Water Amount @ Hot Valve Operation Start | H5: Water Amount @ Hot Valve Operation End
B6: Cold | C6: Cold Valve only | D6: 1 | E6: 0 | F6: ='Water Levels'!C6 -> 28 | G6: None
D7: 2 | E7: 0 | F7: ='Water Levels'!C7 -> 50
D8: 3 | E8: 0 | F8: ='Water Levels'!C8 -> 71
D9: 4 | E9: 0 | F9: ='Water Levels'!C9 -> 93
B10: Warm | C10: Cold + Hot Valves | D10: 1 | E10: 0 | F10: ='Water Levels'!C6/2 -> 14 | G10: =F10 -> 14 | H10: ='Water Levels'!C6 -> 28
D11: 2 | E11: 0 | F11: ='Water Levels'!C7/2 -> 25 | G11: =F11 -> 25 | H11: ='Water Levels'!C7 -> 50
D12: 3 | E12: 0 | F12: ='Water Levels'!C8/2 -> 35.5 | G12: =F12 -> 35.5 | H12: ='Water Levels'!C8 -> 71
D13: 4 | E13: 0 | F13: ='Water Levels'!C9/2 -> 46.5 | G13: =F13 -> 46.5 | H13: ='Water Levels'!C9 -> 93
B14: Hot | C14: Cold + Hot Valves | D14: 1 | E14: 0 | F14: ='Water Levels'!C6/3 -> 9.3333333 | G14: =F14 -> 9.3333333 | H14: ='Water Levels'!C6 -> 28
D15: 2 | E15: 0 | F15: ='Water Levels'!C7/3 -> 16.666667 | G15: =F15 -> 16.666667 | H15: ='Water Levels'!C7 -> 50
D16: 3 | E16: 0 | F16: ='Water Levels'!C8/3 -> 23.666667 | G16: =F16 -> 23.666667 | H16: ='Water Levels'!C8 -> 71
D17: 4 | E17: 0 | F17: ='Water Levels'!C9/3 -> 31 | G17: =F17 -> 31 | H17: ='Water Levels'!C9 -> 93
B19: For Warm & Hot water temp settings, cold water is added to the tub at the beginning of water filling.
B20: Hot valve starts operation only when water pressure sensor gives certain value that indicates that cold water has reached the target water level.'
B21: Then, Hot valve continues to add water until reaching the target water level
B22: For Warm setting only: | D22: If the water level frequency does not change within 30sec after the cold water inlet stops, the following sequence occurs:
D23: 1. The hot water valve continues to operate normally.
D24: 2. The cold water valve reopens to allow water intake again.
B25: Note: | D25: In the hot water setting, error E5 will appear if the hot water supply is not connected to the washing machine.
C26: Target Water Amount

Sheet Things changed in the tables

Sheet Spin Control Specs
B2: A. Spin Control for all Courses Except (Delicates, Wool & Sports Wear) | Q2: Spin Specs:
B3: 1 min spin | E3: 5 min spin | H3: 9 min spin | Q3: Spin pause period after reaching reset water level:
B4: Time (sec) | C4: RPM | E4: Time (sec) | F4: RPM | H4: Time (sec) | I4: RPM | Q4: 150sec
B5: 0 | C5: 0 | E5: 0 | F5: 0 | H5: 0 | I5: 0 | Q5: In case of water level frequency at the beginning of spin equals or not equals reset water level
B6: 15 | C6: 300 | E6: 15 | F6: 300 | H6: 15 | I6: 300
B7: 35 | C7: 300 | E7: 35 | F7: 300 | H7: 35 | I7: 300 | Q7: Spin End:
B8: 155 | C8: 600 | E8: 155 | F8: 600 | H8: 155 | I8: 600 | Q8: No breaking - free fall after reaching spin end time
B9: 160 | C9: 600 | E9: 160 | F9: 600 | H9: 160 | I9: 600 | Q9: Clutch Change (Breaking):
B10: 180 | C10: 700 | E10: 180 | F10: 700 | H10: 180 | I10: 700 | Q10: After RPM sensor stop signal, shift 20sec
B11: 240 | C11: 700 | E11: 480 | F11: 700 | H11: 720 | I11: 700
Q13: Pause State:
Q14: When a user presses pause button during spining twice:
Q15: Spin has to restart again from the balance spin period
Q17: Time displayed:
Q18: Time remaining for the spining will not be modified
B27: B. Spin Control for Delicates, Wool & Sports Wear Courses
B28: 1 min spin | E28: 5 min spin | H28: 9 min spin
B29: Time (sec) | C29: RPM | E29: Time (sec) | F29: RPM | H29: Time (sec) | I29: RPM
B30: 0 | C30: 0 | E30: 0 | F30: 0 | H30: 0 | I30: 0
B31: 15 | C31: 300 | E31: 15 | F31: 300 | H31: 15 | I31: 300
B32: 35 | C32: 300 | E32: 35 | F32: 300 | H32: 35 | I32: 300
B33: 155 | C33: 400 | E33: 155 | F33: 400 | H33: 155 | I33: 400
B34: 240 | C34: 400 | E34: 480 | F34: 400 | H34: 720 | I34: 400

Sheet Mems Specs
B2: MEMS X,Y,Z measuerments start at the beginning of motor motion during spinning only.
B3: MEMS X,Y,Z acceleration is divided by 100
B4: MEMS values are recorded at the beginning of washing machine operation
B5: and at the beginning of spinning MEMS values are compared with the values recorded initially to decide whether there is unbalance or not
B7: MEMS Orientation:
B8: X-Value | C8: UP & Down
B9: Y-Value | C9: Left & Right
B10: Z-Value | C10: Front & Rear
B12: Sharp VE BLDC 11/13kg
B14: Border Values for regular spin | F14: Border Values for factory test mode
B15: X-Value | C15: 10 | F15: X-Value | G15: 10
B16: Y-Value | C16: 28 | F16: Y-Value | G16: 38
B17: Z-Value | C17: 28 | F17: Z-Value | G17: 38
B18: N.H | C18: 40 | F18: N.H | G18: 60
B19: C.H | C19: 5 | F19: C.H | G19: 20

Sheet Fragrance Rinse Spin
B3: Fragrance Rinse ・Spin
BO4: Clutch confirmation operation
F6: 第２槽回転給水 *4 | M6: 1st Shower Rinse
E7: Drain water | F7: *脱水槽が回転し始めたら、 | J7: 1st Spin | L7: *Start Shower water supply | P7: 2nd Spin | Y7: Static rinse Ｗ | AU7: Static rinse Ｆ | BN7: Final Spin
C8: Process | F8: シャワー注水開始 | L8: with starting of basket rotation | AO8: *When drain valve closes, water supply starts. Water is supplied to setting water level.
E9: Drain water | F9: 槽回転給水 | H9: 普通 | I9: Spin 1 | K9: Normal | L9: Shower water supply 1 | N9: Normal | O9: Spin 2 | Q9: Normal | R9: Water supply | S9: Water supply with stir | X9: M6 starting | AB9: M6 | AD9: (Stirring Motion) | AH9: Untangle | AN9: Softener | AO9: Water supply with stir | AT9: Starting | AX9: M6 | AZ9: (Stirring Motion) | BC9: Pause | BD9: M6 | BE9: Pause | BF9: M6 | BG9: Untangle | BM9: Drain water | BN9: Refer to spin control | BP9: Normal
E10: and | H10: (短絡) | K10: (Short) | L10: Motor rpm | M10: Total Time @Water pressure 10 | N10: (Short) | Q10: (Short) | X10: water | AH10: Fixing60" | AN10: valve open | AT10: Water | BM10: and | BP10: (Short)
B11: Capa | C11: Water | D11: Water Amount (Setting w.L) | E11: Clutch | F11: 水圧 | G11: （L/分） | H11: ﾌﾞﾚｰｷ | I11: Motor | K11: Brake | N11: Brake | O11: Motor | Q11: Brake | X11: level | Y11: N. | Z11: Stop | AA11: R. | AB11: Stop | AC11: Rise | AD11: Fall | AE11: Motor | AF11: time | AG11: Drain water & | AN11: When water level is detected as below | AT11: Level | AU11: N. | AV11: Stop | AW11: R. | AX11: Stop | AY11: Rise | AZ11: Fall | BA11: Motor | BB11: time | BG11: max 60" | BM11: Clutch | BN11: Motor | BP11: Brake
B12: city | C12: Level | E12: change | F12: 10 | G12: 15 | I12: rpm | J12: ON | O12: rpm | P12: ON | Y12: R. | AA12: R. | AC12: time | AD12: time | AE12: rpm | AG12: Clutch change | AN12: Softener valve is opened. | AU12: R. | AW12: R. | AY12: time | AZ12: time | BA12: rpm | BM12: change | BN12: rpm | BO12: ON
H13: 停止検知 | J13: 6'00" | L13: 5 rpm Acc = 1 sec. Dec.= 1 sec. | M13: 80" | N13: After stop detection, shift next process (MAX20") | P13: 6'00" | Q13: After stop detection, shift next process (MAX20") | S13: 110 | T13: same as M3 in washing processe | X13: Setting water level | Y13: same as (S) motion in washing processe | AF13: 90" | AO13: 110 | AP13: same as M3 in washing processe | AU13: same as (S) motion in washing processe | BB13: 120" | BC13: 120" | BD13: 120" | BE13: 120" | BF13: 120"
F14: 30" | G14: 20" | H14: 後,次行程
B15: 10 | C15: High | D15: 117 | H15: に進む。 | AN15: Small | AT15: 117 | BN15: 700 | BO15: 6'00"
S18: 110 | AO18: 110
B20: 9 | C20: High | D20: 117 | AN20: Small | AT20: 117 | BN20: 700 | BO20: 6'00"
C21: 1
I23: TOP | O23: TOP | R23: Inlet valve | S23: 110 | AO23: 110
I24: 700 | O24: 700 | R24: ↓
B25: 8 | C25: Middle | D25: 117 | R25: Single | AN25: Small | AT25: 117 | BN25: 700 | BO25: 6'00"
I26: Refer | O26: Refer
I27: to | O27: to | R27: ※After
I28: Spin | O28: Spin | R28: drain valve | S28: 107 | AO28: 107
I29: control | O29: control | R29: close, | AN29: ①Small1
B30: 7 | C30: Middle | D30: 117 | E30: After | R30: Water supply | AT30: 117 | BN30: 700 | BO30: 6'00"
C31: 1 | E31: reaching | K31: After stop | R31: start. | BM31: After
E32: Reset | K32: detection, | AG32: Same spec. as | BG32: Same spec. | BM32: reaching | BP32: After stop
E33: water level | K33: shift next | R33: Water supply | S33: 107 | AG33: Untangle | AO33: 107 | AT33: 117 | BG33: as Untangle | BM33: Reset | BP33: detection,
C34: Middle | E34: 120" | I34: Middle2 | K34: process | R34: to setting | AG34: water current | AN34: ①Small1 | BG34: water current | BM34: water | BP34: clutch
B35: 6 | C35: 2 | D35: 117 | I35: or less | R35: water level | AG35: of wash process | BG35: of wash | BM35: level | BN35: 700 | BO35: 6'00" | BP35: change
K36: (MAX20") | BG36: process | BM36: 120"
L37: Same as Static rinse W | S37: 95 | AG37: Drain valve open | AO37: 85 | BP37: (MAX20")
B38: 5 | C38: Low | D38: 95 | AN38: Reset | AT38: 95 | BN38: 700 | BO38: 6'00"
I39: TOP | AG39: After 35sec.
I40: 700 | S40: None | AG40: reaching
C41: Low | AG41: Rest water
B42: 4 | C42: 1 | D42: 85 | AG42: level. | AN42: Reset | AT42: 85 | BN42: 700 | BO42: 6'00"
O43: TOP | AG43: Clutch change
O44: 700 | AQ44: None
B45: 3 | C45: Small | D45: 75 | AN45: Reset | AT45: 75 | BN45: 700 | BO45: 6'00"
O46: Refer
O47: to
...

Sheet Washing Manual Timings
B2: Time selected by user | D2: M2 | E2: M3 | F2: M4 | G2: Total Time
B3: 3 | D3: 60 | E3: 180 | F3: 180 | G3: =SUM(D3:F3)/60 -> 7
B4: 9 | D4: 60 | E4: 180 | F4: 540 | G4: =SUM(D4:F4)/60 -> 13
B5: 12 | D5: 60 | E5: 180 | F5: 720 | G5: =SUM(D5:F5)/60 -> 16
B6: 18 | D6: 60 | E6: 180 | F6: 1080 | G6: =SUM(D6:F6)/60 -> 22
B7: 5 | D7: 60 | E7: 60 | F7: 180 | G7: =SUM(D7:F7)/60 -> 5 | H7: For soak function only

Sheet Power Cut off
B2: When Power cuts off WM saves data to continue at the same point of operation
B3: However, if power cuts off during wash or rinse , washing restarts from the beginning of motion. Ex. M1, M2 …
B4: WM operates immediately when power come back without pressing pause button again

Sheet Pump Control Specs
B2: First: Time difference between geared motor & pump operation
B3: 1sec - geared motor opens first
B5: Second: Pump operation during overflow*:
B7: Washing Machine | C7: Sharp VE BLDC 11/13kg
B8: Water amount to start overflow protocol | C8: 103L
B9: Water Inlet valve | C9: Closed
B10: Water Level check | C10: Water level is measured during the whole cycle at dynamic state
B11: Door Status | C11: Open/closed
B12: Water Level reached | C12: Selected water level before overflow
B13: Clutch Position during wash & rinse | C13: Wash
B14: *Also check error detection sheet
B16: Third: Pump operation
B17: Continous ON
B18: Max on time is 2.5 minutes and then pump has to be turned off for 10 sec.

Sheet Errors
B2: Error | C2: Error Code | D2: Detection Method | E2: Release Method | F2: Remedy
B3: Water Supply Failure | C3: E5 | D3: • if the water supply is not finished within 20 minutes • Every 10 minutes, the buzzer will alarm for 10 seconds | E3: • lid open and close • check remedy contents • press [START/PAUSE] • the machine operates again | F3: • is the inlet hose connected and the tap opened? • is the inlet hose and the water tap frozen? • is the water supply shut off? • is the inlet valve filter blocked? • is the water valves connected in reverse? • is the water supply pressure low?
B4: Drain Failure | C4: E1 | D4: • if the water level doesn't reach the reset level with 15 minutes from the beginning of the drain • Every 10 minutes, the buzzer will alarm for 10 seconds | E4: • lid open and close • check remedy contents • press [START/PAUSE] • the machine operates again • if after checking all remedy and still error remains, perform the "water level calibration Method" | F4: • is the drain hose frozen? • is the drain hose blocked? • is the drain hose placed too high? • is the end of the drain hose immersed in water?
B5: Lid Opening Failure | C5: E2 | D5: • if the lid is opened during delay start, wash, rinse and spin processes • Every 10 minutes, the buzzer will alarm for 10 seconds | E5: • close the lid, the machine operates automatically again | F5: • is the lid opened?
B6: Unbalance Failure | C6: E3-2 | D6: • if the clothes is collected on one side during spin and the automatic unbalance correction didn’t help to rectify the issue • Every 10 minutes, the buzzer will alarm for 10 seconds | E6: • lid open and close • check remedy contents • press [START/PAUSE] • the machine operates again | F6: • is the clothes in the drum collected on one side? • is the machine is installed on an uneven surface?
B7: Overflow Failure | C7: E6-1 | D7: • Continuous Water Supply Failure • if the water reaches the normal overflow level, drain pump is operating only • if for whatever reason, the water reaches a dangerous water level. The drain pump is operating and the water inlets are closed • if for some reason, the water remains at the dangerous overflow level for 5 minutes. this error alarms • Every 10 minutes, the buzzer will alarm for 10 seconds | E7: • Press Power off • check remedy • close the water tap and drain water manually • if after checking all remedy and still error remains, perform the "water level calibration Method" | F7: • the inlet valve is defected • the drain pump is defected • the water level sensor is defected • the pcb is defected • the pressure tube is loosened or leakaged • Contact Service Center for help
B8: Abnormal Water Level Sensor Reading | C8: E5-1 | D8: • if the detected water level frequency is out of the normal range • Every 10 minutes, the buzzer will alarm for 10 seconds | E8: • Press Power off • check remedy | F8: • the water level sensor is defected • the pcb is defected • Contact Service Center for help
B9: Water Supply Wrong Connection Failure | C9: HE | D9: • if the threshold value of "50" has been exceeded on the cold side valve (when cold option is being selected) • Every 10 minutes, the buzzer will alarm for 10 seconds | E9: • Press Power off • check remedy | F9: • Connect the water supply hose correctly
B10: Abnormal Thermistor Reading | C10: tE | D10: • if the thermistor is short or open circuit • Every 10 minutes, the buzzer will alarm for 10 seconds | E10: • Press Power off • check remedy | F10: • the Thermistor is defected • Contact Service Center for help
B11: Motor CW Rotation Failure | C11: E7-1 | D11: • if the motor is short or open ciruit in the CW direction during wash • Every 10 minutes, the buzzer will alarm for 10 seconds | E11: • Press Power off • check remedy | F11: • the pcb or the motor is defected • Contact Service Center for help
B12: Motor CCW Rotation Failure | C12: E7-2 | D12: • if the motor is short or open ciruit in the CCW direction during wash • Every 10 minutes, the buzzer will alarm for 10 seconds | E12: • Press Power off • check remedy | F12: • the pcb or the motor is defected • Contact Service Center for help
B13: Motor Spin Rotation Failure | C13: E7-3 | D13: • if the motor is short or open ciruit in the CW direction during Spin • Every 10 minutes, the buzzer will alarm for 10 seconds | E13: • Press Power off • check remedy | F13: • the pcb or the motor is defected • Contact Service Center for help
... B19: Abnormal Water When Dry Failure | C19: EA | D19: • if during spin there is water in the tub when it shouldn't • the machine tries to automatically rectifies the issue but after 5 trials if it didn’t success, it displays this error • Every 10 minutes, the buzzer will alarm for 10 seconds | E19: • Press Power off • check remedy • if after checking all remedy and still error remains, perform the "water level calibration Method" | F19: • is the water inlet defected? • is the drain blocked? • is the drain hose placed too high? • is the pressure tube loosened or leakaged? • the water level sensor is defected • the pcb is defected • Contact Service Center for help
B20: CRC Mismatch Failure | C20: CRC
B21: Low Power Failure | C21: LP | D21: • if after power on the voltage level drops below 160v for 5 minutes • Every 10 minutes, the buzzer will alarm for 10 seconds | E21: • Press Power off • check remedy | F21: • is the voltage level ok in the household?
B22: Water Supply High Temp Failure | C22: EE-4 | D22: • if during water filling (hot or warm option is selected), the water temp exceeds the 63 deg threshold • the machine tries to rectifies the issue automatically by opening the cold valve after 30 seconds from exceeding the threshold. If it wasn't successful for 2 minutes, this error appears • Every 10 minutes, the buzzer will alarm for 10 seconds | E22: • Press Power off • check remedy | F22: • the inlet water temp is so high? • the Thermistor is defected • Contact Service Center for help

Sheet Unbalance Protocol

Sheet Door Opening Specs
B3: Error when door is opened | C3: E2 | D3: appears after 0.2sec counted after magnet switch gives 0 signal
B4: WM state after closing door again | C4: continues operation without pressing pause button again
B5: Cases when door is allowed to be open | C5: Door is allowed to be open only during water filling before wash or rinse

Sheet Child Lock Specs
B2: Child Lock is set ON when pressing Soak and Delay Start at the same time during excution
B4: Case | C4: Result | E4: Result
B5: Closed Door | C5: all buttons are disabled EXCEPT Off button
B6: Open Door | C6: Process stops and error E2 apperes with buzzer for 20sec | D6: Case A: door is closed before 20sec period | E6: Washing continues normally
D7: Case B: door is still open after 20sec period | E7: Pump is operated immediately tell reaching reset water level (Clutch Switch to spin mode) WM remains as it is, then turns off after 10min

Sheet Operation
A1: Status | G1: Weight detection | I1: Display | AD1: Matrix LED | AE1: Sound | AF1: OPERATION | AG1: NOTES
I2: Programs LEDs/Switches | U2: Function LEDs | AD2: 7 Segments | AE2: Melody
I4: Regular | J4: Quick | K4: Heavy | L4: Baby Care | M4: Cotton | N4: Delicates | O4: Wool | P4: Quick Rinse | Q4: Jeans | R4: Blanket | S4: Tub Clean | T4: Sports Wear | U4: Water Level LED | Y4: Wash | Z4: Rinse | AA4: Spin | AB4: Child lock LED | AC4: Anti-wrinkle
U5: lvl 1 | V5: Lvl2 | W5: Lvl 3 | X5: lvl 4
A6: ON | B6: First 0.5 sec. | I6: X | J6: X | K6: X | L6: X | M6: X | N6: X | O6: X | P6: X | Q6: X | R6: X | S6: X | T6: X | U6: X | V6: X | W6: X | X6: X | Y6: X | Z6: X | AA6: X | AB6: X | AC6: X | AD6: Displays all digits | AE6: APP_BUZZER_START_UP_TONE | AG6: All LEDs are ON
